<?xml version="1.0" ?>
<!--
  Ignition Gazebo joint position controller plugin demo

  Try sending joint position commands:

    ign topic -t "/rotor_cmd" -m ignition.msgs.Double -p "data: -1.0"

    ign topic -t "/rotor_cmd" -m ignition.msgs.Double -p "data: 1.0"
-->
<sdf version="1.8">
    <world name="left_arm_ik_con">
        <physics name="1ms" type="ignored">
            <max_step_size>0.001</max_step_size>
            <real_time_factor>1.0</real_time_factor>
        </physics>
        <plugin
            filename="libignition-gazebo-physics-system.so"
            name="ignition::gazebo::systems::Physics">
        </plugin>
        <plugin
            filename="libignition-gazebo-user-commands-system.so"
            name="ignition::gazebo::systems::UserCommands">
        </plugin>
        <plugin
            filename="libignition-gazebo-scene-broadcaster-system.so"
            name="ignition::gazebo::systems::SceneBroadcaster">
        </plugin>

         <gui fullscreen="0">

        <!-- 3D scene -->
        <plugin filename="GzScene3D" name="3D View">
            <ignition-gui>
            <title>3D View</title>
            <property type="bool" key="showTitleBar">false</property>
            <property type="string" key="state">docked</property>
            </ignition-gui>

            <engine>ogre2</engine>
            <scene>scene</scene>
            <ambient_light>0.4 0.4 0.4</ambient_light>
            <background_color>0.8 0.8 0.8</background_color>
            <camera_pose>2 2 2 0 0.5 -2.5</camera_pose>
        </plugin>

        <!-- World control -->
        <plugin filename="WorldControl" name="World control">
            <ignition-gui>
            <title>World control</title>
            <property type="bool" key="showTitleBar">false</property>
            <property type="bool" key="resizable">false</property>
            <property type="double" key="height">72</property>
            <property type="double" key="width">121</property>
            <property type="double" key="z">1</property>

            <property type="string" key="state">floating</property>
            <anchors target="3D View">
                <line own="left" target="left"/>
                <line own="bottom" target="bottom"/>
            </anchors>
            </ignition-gui>

            <play_pause>true</play_pause>
            <step>true</step>
            <start_paused>true</start_paused>

        </plugin>

        <!-- World statistics -->
        <plugin filename="WorldStats" name="World stats">
            <ignition-gui>
            <title>World stats</title>
            <property type="bool" key="showTitleBar">false</property>
            <property type="bool" key="resizable">false</property>
            <property type="double" key="height">110</property>
            <property type="double" key="width">290</property>
            <property type="double" key="z">1</property>

            <property type="string" key="state">floating</property>
            <anchors target="3D View">
                <line own="right" target="right"/>
                <line own="bottom" target="bottom"/>
            </anchors>
            </ignition-gui>

            <sim_time>true</sim_time>
            <real_time>true</real_time>
            <real_time_factor>true</real_time_factor>
            <iterations>true</iterations>
        </plugin>

        <plugin filename="JointPositionController" name="JointPositionController">
            <ignition-gui>
            <property type="double" key="height">600</property>
            <property type="double" key="width">400</property>

            <property type="string" key="state">floating</property>
            <anchors target="3D View">
                <line own="right" target="right"/>
                <line own="top" target="top"/>
            </anchors>
            </ignition-gui>
            <model_name>body</model_name>
        </plugin>
        </gui> 

        <light type="directional" name="sun">
            <cast_shadows>true</cast_shadows>
            <pose>0 0 10 0 0 0</pose>
            <diffuse>0.8 0.8 0.8 1</diffuse>
            <specular>0.2 0.2 0.2 1</specular>
            <attenuation>
                <range>1000</range>
                <constant>0.9</constant>
                <linear>0.01</linear>
                <quadratic>0.001</quadratic>
            </attenuation>
            <direction>-0.5 0.1 -0.9</direction>
        </light>

        <model name="ground_plane">
            <static>true</static>
            <link name="link">
                <collision name="collision">
                <geometry>
                    <plane>
                    <normal>0 0 1</normal>
                    </plane>
                </geometry>
                </collision>
                <visual name="visual">
                <geometry>
                    <plane>
                    <normal>0 0 1</normal>
                    <size>1000 1000</size>
                    </plane>
                </geometry>
                <material>
                    <ambient>0.8 0.8 0.8 1</ambient>
                    <diffuse>0.8 0.8 0.8 1</diffuse>
                    <specular>0.8 0.8 0.8 1</specular>
                </material>
                </visual>
            </link>
        </model>

        <model name="body">
            <joint name="weld" type="fixed">
                <pose>0 0 0 0 0 0</pose>
                <parent>world</parent>
                <child>base_link</child>
            </joint>
            <link name="base_link">
                <pose>0 0 25 0 0 0</pose>
                <visual name="visual">
                    <geometry>
                        <box>
                            <size>1 1 50</size> 
                        </box>
                    </geometry>
                </visual>
                <collision name="collision">
                    <geometry>
                    <box>
                        <size>1 1 50</size> 
                    </box>
                    </geometry>
                </collision>
            </link>
            <joint name ="ID101" type="revolute">
                <pose relative_to='base_link'>0.5 0 23 0 0 0</pose>
                <parent>world</parent>
                <child>l1_link</child>
                <axis>
                    <xyz>1 0 0</xyz>
                    <limit>
                        <!-- <lower>-1.57</lower>
                        <upper>1.57</upper> -->
                        <lower>-3.14</lower>
                        <upper>3.14</upper>
                    </limit>
                    <dynamics>
                        <damping>0.1</damping>
                    </dynamics>
                </axis>
            </joint>
            <link name="l1_link">
                <pose relative_to='ID101'>1.75 0 0 0 0 0</pose>
                <inertial>
                    <mass>0.00001</mass>
                    <inertia>
                        <ixx>0.001</ixx>
                        <ixy>0.0</ixy>
                        <ixz>0.0</ixz>
                        <iyy>0.001</iyy>
                        <iyz>0.0</iyz>
                        <izz>0.001</izz>
                    </inertia>
                </inertial>
                <visual name="visual">
                    <geometry>
                        <box>
                            <size>3.5 0.5 0.5</size> 
                        </box>
                    </geometry>
                    <material>
                        <ambient>0.0 1 0.0 1</ambient>
                        <diffuse>0.0 1 0.0 1</diffuse>
                        <specular>0.0 1 0.0 1</specular>
                    </material>
                </visual>
                <collision name="collision">
                    <geometry>
                        <box>
                            <size>3.5 0.5 0.5</size> 
                        </box>
                    </geometry>
                </collision>
            </link>
            <joint name ="ID102" type="revolute">
                <pose relative_to='l1_link'>1.75 0 0 0 0 0</pose>
                <parent>l1_link</parent>
                <child>l2_link</child>
                <axis>
                    <xyz>0 0 1</xyz>
                    <limit>
                        <!-- <lower>-1.57</lower>
                        <upper>1.57</upper> -->
                        <lower>-3.14</lower>
                        <upper>3.14</upper>                        
                    </limit>
                    <dynamics>
                        <damping>0.1</damping>
                    </dynamics>
                </axis>
            </joint>    
            <link name="l2_link">
                <pose relative_to='ID102'>2.75 0 0 0 0 0</pose>
                <inertial>
                    <mass>0.00001</mass>
                    <inertia>
                        <ixx>0.001</ixx>
                        <ixy>0.0</ixy>
                        <ixz>0.0</ixz>
                        <iyy>0.001</iyy>
                        <iyz>0.0</iyz>
                        <izz>0.001</izz>
                    </inertia>                    
                </inertial>
                <visual name="visual">
                    <geometry>
                        <box>
                            <size>5.5 0.5 0.5</size> 
                        </box>
                    </geometry>
                </visual>
                <collision name="collision">
                    <geometry>
                        <box>
                            <size>5.5 0.5 0.5</size> 
                        </box>
                    </geometry>
                </collision>
            </link>
            <joint name ="ID103" type="revolute">
                <pose relative_to='l2_link'>2.75 0 0 0 0 0</pose>
                <parent>l2_link</parent>
                <child>l3_link</child>
                <axis>
                    <xyz>1 0 0</xyz>
                    <limit>
                        <!-- <lower>-1.57</lower>
                        <upper>1.57</upper> -->
                        <lower>-3.14</lower>
                        <upper>3.14</upper>                        
                    </limit>
                    <dynamics>
                        <damping>0.1</damping>
                    </dynamics>
                </axis>
            </joint>    
            <link name="l3_link">
                <pose relative_to='ID103'>5.25 0 0 0 0 0</pose>
                <inertial>
                    <mass>0.00001</mass>
                    <inertia>
                        <ixx>0.001</ixx>
                        <ixy>0.0</ixy>
                        <ixz>0.0</ixz>
                        <iyy>0.001</iyy>
                        <iyz>0.0</iyz>
                        <izz>0.001</izz>   
                    </inertia>                    
                </inertial>
                <visual name="visual">
                    <geometry>
                        <box>
                            <size>10.5 0.5 0.5</size> 
                        </box>
                    </geometry>
                    <material>
                        <ambient>0.0 1 0.0 1</ambient>
                        <diffuse>0.0 1 0.0 1</diffuse>
                        <specular>0.0 1 0.0 1</specular>
                    </material>                    
                </visual>
                <collision name="collision">
                    <geometry>
                        <box>
                            <size>10.5 0.5 0.5</size> 
                        </box>
                    </geometry>
                </collision>
            </link>     
            <joint name ="ID104" type="revolute">
                <pose relative_to='l3_link'>5.25 0 0 0 0 0</pose>
                <parent>l3_link</parent>
                <child>l4_link</child>
                <axis>
                    <xyz>0 1 0</xyz>
                    <limit>
                        <!-- <lower>-1.74</lower>
                        <upper>1.74</upper> -->
                        <lower>-3.14</lower>
                        <upper>3.14</upper>    
                    </limit>
                    <dynamics>
                        <damping>0.1</damping>
                    </dynamics>
                </axis>
            </joint>    
            <link name="l4_link">
                <pose relative_to='ID104'>3.5 0 0 0 0 0</pose>
                <inertial>
                    <mass>0.00001</mass>
                    <inertia>
                        <ixx>0.001</ixx>
                        <ixy>0.0</ixy>
                        <ixz>0.0</ixz>
                        <iyy>0.001</iyy>
                        <iyz>0.0</iyz>
                        <izz>0.001</izz>
                    </inertia>                    
                </inertial>
                <visual name="visual">
                    <geometry>
                        <box>
                            <size>7 0.5 0.5</size> 
                        </box>
                    </geometry>
                </visual>
                <collision name="collision">
                    <geometry>
                        <box>
                            <size>7 0.5 0.5</size> 
                        </box>
                    </geometry>
                </collision>
            </link>
            <joint name ="ID105" type="revolute">
                <pose relative_to='l4_link'>3.5 0 0 0 0 0</pose>
                <parent>l4_link</parent>
                <child>l5_link</child>
                <axis>
                    <xyz>0 1 0</xyz>
                    <limit>
                        <!-- <lower>-1.57</lower>
                        <upper>1.74</upper> -->
                        <lower>-3.14</lower>
                        <upper>3.14</upper>
                    </limit>
                    <dynamics>
                        <damping>0.1</damping>
                    </dynamics>
                </axis>
            </joint>    
            <link name="l5_link">
                <pose relative_to='ID105'>7.5 0 0 0 0 0</pose>
                <inertial>
                    <mass>0.00001</mass>
                    <inertia>
                        <ixx>0.001</ixx>
                        <ixy>0.0</ixy>
                        <ixz>0.0</ixz>
                        <iyy>0.001</iyy>
                        <iyz>0.0</iyz>
                        <izz>0.001</izz>
                    </inertia>                    
                </inertial>
                <visual name="visual">
                    <geometry>
                        <box>
                            <size>15 0.5 0.5</size> 
                        </box>
                    </geometry>
                    <material>
                        <ambient>0.0 1 0.0 1</ambient>
                        <diffuse>0.0 1 0.0 1</diffuse>
                        <specular>0.0 1 0.0 1</specular>
                    </material>
                </visual>
                <collision name="collision">
                    <geometry>
                        <box>
                            <size>15 0.5 0.5</size> 
                        </box>
                    </geometry>
                </collision>
            </link>
            <plugin
                filename="ignition-gazebo-joint-position-controller-system"
                name="gz::sim::systems::JointPositionController">
                <joint_name>ID101</joint_name>
                <topic>rotor_cmd1</topic>
                <p_gain>1</p_gain>
                <i_gain>0.1</i_gain>
                <d_gain>0.01</d_gain>
                <i_max>1</i_max>
                <i_min>-1</i_min>
                <cmd_max>10</cmd_max>
                <cmd_min>-10</cmd_min>
            </plugin>    
            <plugin
                filename="ignition-gazebo-joint-position-controller-system"
                name="gz::sim::systems::JointPositionController">
                <joint_name>ID102</joint_name>
                <topic>rotor_cmd2</topic>
                <p_gain>1010</p_gain>
                <i_gain>0.1</i_gain>
                <d_gain>0.01</d_gain>
                <i_max>1</i_max>
                <i_min>-1</i_min>
                <cmd_max>10</cmd_max>
                <cmd_min>-10</cmd_min>
            </plugin>
            <plugin
                filename="ignition-gazebo-joint-position-controller-system"
                name="gz::sim::systems::JointPositionController">
                <joint_name>ID103</joint_name>
                <topic>rotor_cmd3</topic>
                <p_gain>1</p_gain>
                <i_gain>0.1</i_gain>
                <d_gain>0.01</d_gain>
                <i_max>1</i_max>
                <i_min>-1</i_min>
                <cmd_max>10</cmd_max>
                <cmd_min>-10</cmd_min>
            </plugin>    
            <plugin
                filename="ignition-gazebo-joint-position-controller-system"
                name="gz::sim::systems::JointPositionController">
                <joint_name>ID104</joint_name>
                <topic>rotor_cmd4</topic>
                <p_gain>1</p_gain>
                <i_gain>0.1</i_gain>
                <d_gain>0.01</d_gain>
                <i_max>1</i_max>
                <i_min>-1</i_min>
                <cmd_max>10</cmd_max>
                <cmd_min>-10</cmd_min>
            </plugin> 
            <plugin
                filename="ignition-gazebo-joint-position-controller-system"
                name="gz::sim::systems::JointPositionController">
                <joint_name>ID105</joint_name>
                <topic>rotor_cmd5</topic>
                <p_gain>1</p_gain>
                <i_gain>0.1</i_gain>
                <d_gain>0.01</d_gain>
                <i_max>1</i_max>
                <i_min>-1</i_min>
                <cmd_max>10</cmd_max>
                <cmd_min>-10</cmd_min>
            </plugin>       
        </model>
    </world>
</sdf> 

